Workbook

Sheet 🔐 MD5
B1: 🔐 MD5 Hash Calculator — Pure Formulas, No VBA
B2: Requires Excel 2013+ · Uses only INT, MOD, MID, CODE — no BITOR/BITAND macros
B4: ✏️ TYPE YOUR WORD HERE (1–7 ASCII characters):
B5: hello
B7: 🔑 MD5 RESULT:
B8: ='⚙️ Compute'!E2 -> 5d41402abc4b2a76b9719d911017c592
B10: 📌 Sheets: 📖 How MD5 Works | 🔤 ASCII Encoding | 📦 MD5 Constants | ⚙️ Compute
B12: ✅ Verified: "hello" → 5d41402abc4b2a76b9719d911017c592 | "abc" → 900150983cd24fb0d6963f7d28e17f72 | "test" → 098f6bcd4621d373cade4e832627b4f6
B13: ⚠️ Max input: 7 characters · ASCII only · Requires Excel 2013+ (for INT/MOD/MID — no BITOR/BITAND needed)

Sheet 📖 How MD5 Works
B1: 📖 How MD5 Works — Algorithm Explanation
B2: Step 1 · Input
B3: Convert each character to its ASCII byte code. 'hello' → [104, 101, 108, 108, 111] = 5 bytes.
B4: Step 2 · Padding
B5: Append byte 0x80 after the message, then zero bytes until total length ≡ 56 (mod 64). For ≤7-byte input: byte[len]=128, bytes[len+1..55]=0.
B6: Step 3 · Length
B7: Append the original bit-length as a 64-bit little-endian integer in bytes 56–63. 'hello'=5 bytes=40 bits → bytes 56-59=[40,0,0,0], 60-63=[0,0,0,0]. Now total=512 bits=16 words M[0..15].
B8: Step 4 · Init state
B9: Four 32-bit magic constants: A₀=0x67452301 B₀=0xEFCDAB89 C₀=0x98BADCFE D₀=0x10325476
B10: Step 5 · 64 ops
B11: Four rounds × 16 ops. Each op: new_B = B + ROL32( A + F(B,C,D) + M[g] + K[i], r[i] ) new_A = D, new_C = B, new_D = C
B12: Round functions
... B21: Since Excel has no 32-bit integer type, we implement: · AND32(a,b): byte-decomposition into 4×8-bit BITANDs using INT/MOD arithmetic · OR32(a,b) = a+b−AND32(a,b) | XOR32(a,b) = a+b−2×AND32(a,b) · NOT32(a) = 4294967295−a · ROL32(x,n) = MOD( MOD(x,2^(32−n))×2^n + INT(x/2^(32−n)), 2³² ) · ADD32(a,b) = MOD(a+b, 2³²) Each of the 64 steps is one row on the ⚙️ Compute sheet.

Sheet 🔤 ASCII Encoding
B1: 🔤 Input → ASCII → Binary bits
B2: Pos | C2: Char | D2: ASCII | E2: Hex | F2: b7 | G2: b6 | H2: b5 | I2: b4 | J2: b3 | K2: b2 | L2: b1 | M2: b0
B3: 1 | C3: =IF(LEN('🔐 MD5'!B5)>=1,MID('🔐 MD5'!B5,1,1),"-") -> h | D3: =IF(C3<>"-",CODE(C3),"") -> 104 | E3: =IF(D3<>"",MID("0123456789abcdef",MOD(INT(D3/16),16)+1,1)&MID("0123456789abcdef",MOD(MOD(D3,16),16)+1,1),"") -> 68 | F3: =IF(D3<>"",MOD(INT(D3/2^7),2),"") -> 0 | G3: =IF(D3<>"",MOD(INT(D3/2^6),2),"") -> 1 | H3: =IF(D3<>"",MOD(INT(D3/2^5),2),"") -> 1 | I3: =IF(D3<>"",MOD(INT(D3/2^4),2),"") -> 0 | J3: =IF(D3<>"",MOD(INT(D3/2^3),2),"") -> 1 | K3: =IF(D3<>"",MOD(INT(D3/2^2),2),"") -> 0 | L3: =IF(D3<>"",MOD(INT(D3/2^1),2),"") -> 0 | M3: =IF(D3<>"",MOD(INT(D3/2^0),2),"") -> 0
B4: 2 | C4: =IF(LEN('🔐 MD5'!B5)>=2,MID('🔐 MD5'!B5,2,1),"-") -> e | D4: =IF(C4<>"-",CODE(C4),"") -> 101 | E4: =IF(D4<>"",MID("0123456789abcdef",MOD(INT(D4/16),16)+1,1)&MID("0123456789abcdef",MOD(MOD(D4,16),16)+1,1),"") -> 65 | F4: =IF(D4<>"",MOD(INT(D4/2^7),2),"") -> 0 | G4: =IF(D4<>"",MOD(INT(D4/2^6),2),"") -> 1 | H4: =IF(D4<>"",MOD(INT(D4/2^5),2),"") -> 1 | I4: =IF(D4<>"",MOD(INT(D4/2^4),2),"") -> 0 | J4: =IF(D4<>"",MOD(INT(D4/2^3),2),"") -> 0 | K4: =IF(D4<>"",MOD(INT(D4/2^2),2),"") -> 1 | L4: =IF(D4<>"",MOD(INT(D4/2^1),2),"") -> 0 | M4: =IF(D4<>"",MOD(INT(D4/2^0),2),"") -> 1
B5: 3 | C5: =IF(LEN('🔐 MD5'!B5)>=3,MID('🔐 MD5'!B5,3,1),"-") -> l | D5: =IF(C5<>"-",CODE(C5),"") -> 108 | E5: =IF(D5<>"",MID("0123456789abcdef",MOD(INT(D5/16),16)+1,1)&MID("0123456789abcdef",MOD(MOD(D5,16),16)+1,1),"") -> 6c | F5: =IF(D5<>"",MOD(INT(D5/2^7),2),"") -> 0 | G5: =IF(D5<>"",MOD(INT(D5/2^6),2),"") -> 1 | H5: =IF(D5<>"",MOD(INT(D5/2^5),2),"") -> 1 | I5: =IF(D5<>"",MOD(INT(D5/2^4),2),"") -> 0 | J5: =IF(D5<>"",MOD(INT(D5/2^3),2),"") -> 1 | K5: =IF(D5<>"",MOD(INT(D5/2^2),2),"") -> 1 | L5: =IF(D5<>"",MOD(INT(D5/2^1),2),"") -> 0 | M5: =IF(D5<>"",MOD(INT(D5/2^0),2),"") -> 0
B6: 4 | C6: =IF(LEN('🔐 MD5'!B5)>=4,MID('🔐 MD5'!B5,4,1),"-") -> l | D6: =IF(C6<>"-",CODE(C6),"") -> 108 | E6: =IF(D6<>"",MID("0123456789abcdef",MOD(INT(D6/16),16)+1,1)&MID("0123456789abcdef",MOD(MOD(D6,16),16)+1,1),"") -> 6c | F6: =IF(D6<>"",MOD(INT(D6/2^7),2),"") -> 0 | G6: =IF(D6<>"",MOD(INT(D6/2^6),2),"") -> 1 | H6: =IF(D6<>"",MOD(INT(D6/2^5),2),"") -> 1 | I6: =IF(D6<>"",MOD(INT(D6/2^4),2),"") -> 0 | J6: =IF(D6<>"",MOD(INT(D6/2^3),2),"") -> 1 | K6: =IF(D6<>"",MOD(INT(D6/2^2),2),"") -> 1 | L6: =IF(D6<>"",MOD(INT(D6/2^1),2),"") -> 0 | M6: =IF(D6<>"",MOD(INT(D6/2^0),2),"") -> 0
B7: 5 | C7: =IF(LEN('🔐 MD5'!B5)>=5,MID('🔐 MD5'!B5,5,1),"-") -> o | D7: =IF(C7<>"-",CODE(C7),"") -> 111 | E7: =IF(D7<>"",MID("0123456789abcdef",MOD(INT(D7/16),16)+1,1)&MID("0123456789abcdef",MOD(MOD(D7,16),16)+1,1),"") -> 6f | F7: =IF(D7<>"",MOD(INT(D7/2^7),2),"") -> 0 | G7: =IF(D7<>"",MOD(INT(D7/2^6),2),"") -> 1 | H7: =IF(D7<>"",MOD(INT(D7/2^5),2),"") -> 1 | I7: =IF(D7<>"",MOD(INT(D7/2^4),2),"") -> 0 | J7: =IF(D7<>"",MOD(INT(D7/2^3),2),"") -> 1 | K7: =IF(D7<>"",MOD(INT(D7/2^2),2),"") -> 1 | L7: =IF(D7<>"",MOD(INT(D7/2^1),2),"") -> 1 | M7: =IF(D7<>"",MOD(INT(D7/2^0),2),"") -> 1
B8: 6 | C8: =IF(LEN('🔐 MD5'!B5)>=6,MID('🔐 MD5'!B5,6,1),"-") -> - | D8: =IF(C8<>"-",CODE(C8),"") | E8: =IF(D8<>"",MID("0123456789abcdef",MOD(INT(D8/16),16)+1,1)&MID("0123456789abcdef",MOD(MOD(D8,16),16)+1,1),"") | F8: =IF(D8<>"",MOD(INT(D8/2^7),2),"") | G8: =IF(D8<>"",MOD(INT(D8/2^6),2),"") | H8: =IF(D8<>"",MOD(INT(D8/2^5),2),"") | I8: =IF(D8<>"",MOD(INT(D8/2^4),2),"") | J8: =IF(D8<>"",MOD(INT(D8/2^3),2),"") | K8: =IF(D8<>"",MOD(INT(D8/2^2),2),"") | L8: =IF(D8<>"",MOD(INT(D8/2^1),2),"") | M8: =IF(D8<>"",MOD(INT(D8/2^0),2),"")
B9: 7 | C9: =IF(LEN('🔐 MD5'!B5)>=7,MID('🔐 MD5'!B5,7,1),"-") -> - | D9: =IF(C9<>"-",CODE(C9),"") | E9: =IF(D9<>"",MID("0123456789abcdef",MOD(INT(D9/16),16)+1,1)&MID("0123456789abcdef",MOD(MOD(D9,16),16)+1,1),"") | F9: =IF(D9<>"",MOD(INT(D9/2^7),2),"") | G9: =IF(D9<>"",MOD(INT(D9/2^6),2),"") | H9: =IF(D9<>"",MOD(INT(D9/2^5),2),"") | I9: =IF(D9<>"",MOD(INT(D9/2^4),2),"") | J9: =IF(D9<>"",MOD(INT(D9/2^3),2),"") | K9: =IF(D9<>"",MOD(INT(D9/2^2),2),"") | L9: =IF(D9<>"",MOD(INT(D9/2^1),2),"") | M9: =IF(D9<>"",MOD(INT(D9/2^0),2),"")

Sheet 📦 MD5 Constants
B1: 📦 MD5 Constants — K[i] (from sine) and r[i] (shift amounts)
B2: K[i] = floor(2³² × |sin(i+1)|) used in step: temp = A + F(B,C,D) + M[g] + K[i]
B3: i | C3: K[i] decimal | D3: K[i] hex | E3: Round | G3: i | H3: r[i] | I3: Round
B4: 0 | C4: 3614090360 | D4: 0xD76AA478 | E4: Round 1 (F) | G4: 0 | H4: 7 | I4: Round 1 (F)
B5: 1 | C5: 3905402710 | D5: 0xE8C7B756 | E5: Round 1 (F) | G5: 1 | H5: 12 | I5: Round 1 (F)
B6: 2 | C6: 606105819 | D6: 0x242070DB | E6: Round 1 (F) | G6: 2 | H6: 17 | I6: Round 1 (F)
B7: 3 | C7: 3250441966 | D7: 0xC1BDCEEE | E7: Round 1 (F) | G7: 3 | H7: 22 | I7: Round 1 (F)
B8: 4 | C8: 4118548399 | D8: 0xF57C0FAF | E8: Round 1 (F) | G8: 4 | H8: 7 | I8: Round 1 (F)
B9: 5 | C9: 1200080426 | D9: 0x4787C62A | E9: Round 1 (F) | G9: 5 | H9: 12 | I9: Round 1 (F)
B10: 6 | C10: 2821735955 | D10: 0xA8304613 | E10: Round 1 (F) | G10: 6 | H10: 17 | I10: Round 1 (F)
B11: 7 | C11: 4249261313 | D11: 0xFD469501 | E11: Round 1 (F) | G11: 7 | H11: 22 | I11: Round 1 (F)
B12: 8 | C12: 1770035416 | D12: 0x698098D8 | E12: Round 1 (F) | G12: 8 | H12: 7 | I12: Round 1 (F)
B13: 9 | C13: 2336552879 | D13: 0x8B44F7AF | E13: Round 1 (F) | G13: 9 | H13: 12 | I13: Round 1 (F)
B14: 10 | C14: 4294925233 | D14: 0xFFFF5BB1 | E14: Round 1 (F) | G14: 10 | H14: 17 | I14: Round 1 (F)
B15: 11 | C15: 2304563134 | D15: 0x895CD7BE | E15: Round 1 (F) | G15: 11 | H15: 22 | I15: Round 1 (F)
... B67: 63 | C67: 3951481745 | D67: 0xEB86D391 | E67: Round 4 (I) | G67: 63 | H67: 21 | I67: Round 4 (I)

Sheet ⚙️ Compute
B1: ⚙️ MD5 Computation — 64 Steps (pure INT/MOD arithmetic, no BITOR/BITAND)
B2: MD5 HASH: | E2: =LOWER(MID("0123456789abcdef",MOD(INT((MOD(INT(C70/256^0),256))/16),16)+1,1)&MID("0123456789abcdef",MOD(MOD((MOD(INT(C70/256^0),256)),16),16)+1,1)&MID("0123456789abcdef",MOD(INT((MOD(INT(C70/256^1),256))/16),16)+1,1)&MID("0123456789abcdef",MOD(MOD((MOD(INT(C70/256^1),256)),16),16)+1,1)&MID("0123456789abcdef",MOD(INT((MOD(INT(C70/256^2),256))/16),16)+1,1)&MID("0123456789abcdef",MOD(MOD((MOD(INT(C70/256^2),256)),16),16)+1,1)&MID("0123456789abcdef",MOD(INT((MOD(INT(C70/256^3),256))/16),16)+1,1)&MID("0123456789abcdef",MOD(MOD((MOD(INT(C70/256^3),256)),16),16)+1,1)&MID("0123456789abcdef",MOD(INT((MOD(INT(D70/256^0),256))/16),16)+1,1)&MID("0123456789abcdef",MOD(MOD((MOD(INT(D70/256^0),256)),16),16)+1,1)&MID("0123456789abcdef",MOD(INT((MOD(INT(D70/256^1),256))/16),16)+1,1)&MID("0123456789abcdef",MOD(MOD((MOD(INT(D70/256^1),256)),16),16)+1,1)&MID("0123456789abcdef",MOD(INT((MOD(INT(D70/256^2),256))/16),16)+1,1)&MID("0123456789abcdef",MOD(MOD((MOD(INT(D70/256^2),256)),16),16)+1,1)&MID("0123456789abcdef",MOD(INT((MOD(INT(D70/256^3),256))/16),16)+1,1)&MID("0123456789abcdef",MOD(MOD((MOD(INT(D70/256^3),256)),16),16)+1,1)&MID("0123456789abcdef",MOD(INT((MOD(INT(E70/256^0),256))/16),16)+1,1)&MID("0123456789abcdef",MOD(MOD((MOD(INT(E70/256^0),256)),16),16)+1,1)&MID("0123456789abcdef",MOD(INT((MOD(INT(E70/256^1),256))/16),16)+1,1)&MID("0123456789abcdef",MOD(MOD((MOD(INT(E70/256^1),256)),16),16)+1,1)&MID("0123456789abcdef",MOD(INT((MOD(INT(E70/256^2),256))/16),16)+1,1)&MID("0123456789abcdef",MOD(MOD((MOD(INT(E70/256^2),256)),16),16)+1,1)&MID("0123456789abcdef",MOD(INT((MOD(INT(E70/256^3),256))/16),16)+1,1)&MID("0123456789abcdef",MOD(MOD((MOD(INT(E70/256^3),256)),16),16)+1,1)&MID("0123456789abcdef",MOD(INT((MOD(INT(F70/256^0),256))/16),16)+1,1)&MID("0123456789abcdef",MOD(MOD((MOD(INT(F70/256^0),256)),16),16)+1,1)&MID("0123456789abcdef",MOD(INT((MOD(INT(F70/256^1),256))/16),16)+1,1)&MID("0123456789abcdef",MOD(MOD((MOD(INT(F70/256^1),256)),16),16)+1,1)&MID("0123456789abcdef",MOD(INT((MOD(INT(F70/256^2),256))/16),16)+1,1)&MID("0123456789abcdef",MOD(MOD((MOD(INT(F70/256^2),256)),16),16)+1,1)&MID("0123456789abcdef",MOD(INT((MOD(INT(F70/256^3),256))/16),16)+1,1)&MID("0123456789abcdef",MOD(MOD((MOD(INT(F70/256^3),256)),16),16)+1,1)) -> 5d41402abc4b2a76b9719d911017c592
B3: Each step: new_B = ADD32( B, ROL32( ADD32(A, FUNC(B,C,D), M[g], K[i]), r[i] ) ) new_A=D new_C=B new_D=C | BITAND implemented as pure INT/MOD byte expansion
B4: Step | C4: A | D4: B | E4: C | F4: D | G4: BA1 | H4: BA2 | I4: BA3 | J4: FUNC | K4: M[g] | L4: K[i] | M4: r | N4: A+F+M+K | O4: ROL | P4: new_B | Q4: Note
B5: INIT | C5: 1732584193 | D5: 4023233417 | E5: 2562383102 | F5: 271733878 | G5: A₀=0x67452301 B₀=0xEFCDAB89 C₀=0x98BADCFE D₀=0x10325476
B6: 1 | C6: =F5 -> 271733878 | D6: =MOD(D5+O6,4294967296) -> 3679623978 | E6: =D5 -> 4023233417 | F6: =E5 -> 2562383102 | G6: =((MOD(INT(MOD(INT((D5)/1),256)/2^0),2)*MOD(INT(MOD(INT((E5)/1),256)/2^0),2)*1+MOD(INT(MOD(INT((D5)/1),256)/2^1),2)*MOD(INT(MOD(INT((E5)/1),256)/2^1),2)*2+MOD(INT(MOD(INT((D5)/1),256)/2^2),2)*MOD(INT(MOD(INT((E5)/1),256)/2^2),2)*4+MOD(INT(MOD(INT((D5)/1),256)/2^3),2)*MOD(INT(MOD(INT((E5)/1),256)/2^3),2)*8+MOD(INT(MOD(INT((D5)/1),256)/2^4),2)*MOD(INT(MOD(INT((E5)/1),256)/2^4),2)*16+MOD(INT(MOD(INT((D5)/1),256)/2^5),2)*MOD(INT(MOD(INT((E5)/1),256)/2^5),2)*32+MOD(INT(MOD(INT((D5)/1),256)/2^6),2)*MOD(INT(MOD(INT((E5)/1),256)/2^6),2)*64+MOD(INT(MOD(INT((D5)/1),256)/2^7),2)*MOD(INT(MOD(INT((E5)/1),256)/2^7),2)*128)*1+(MOD(INT(MOD(INT((D5)/256),256)/2^0),2)*MOD(INT(MOD(INT((E5)/256),256)/2^0),2)*1+MOD(INT(MOD(INT((D5)/256),256)/2^1),2)*MOD(INT(MOD(INT((E5)/256),256)/2^1),2)*2+MOD(INT(MOD(INT((D5)/256),256)/2^2),2)*MOD(INT(MOD(INT((E5)/256),256)/2^2),2)*4+MOD(INT(MOD(INT((D5)/256),256)/2^3),2)*MOD(INT(MOD(INT((E5)/256),256)/2^3),2)*8+MOD(INT(MOD(INT((D5)/256),256)/2^4),2)*MOD(INT(MOD(INT((E5)/256),256)/2^4),2)*16+MOD(INT(MOD(INT((D5)/256),256)/2^5),2)*MOD(INT(MOD(INT((E5)/256),256)/2^5),2)*32+MOD(INT(MOD(INT((D5)/256),256)/2^6),2)*MOD(INT(MOD(INT((E5)/256),256)/2^6),2)*64+MOD(INT(MOD(INT((D5)/256),256)/2^7),2)*MOD(INT(MOD(INT((E5)/256),256)/2^7),2)*128)*256+(MOD(INT(MOD(INT((D5)/65536),256)/2^0),2)*MOD(INT(MOD(INT((E5)/65536),256)/2^0),2)*1+MOD(INT(MOD(INT((D5)/65536),256)/2^1),2)*MOD(INT(MOD(INT((E5)/65536),256)/2^1),2)*2+MOD(INT(MOD(INT((D5)/65536),256)/2^2),2)*MOD(INT(MOD(INT((E5)/65536),256)/2^2),2)*4+MOD(INT(MOD(INT((D5)/65536),256)/2^3),2)*MOD(INT(MOD(INT((E5)/65536),256)/2^3),2)*8+MOD(INT(MOD(INT((D5)/65536),256)/2^4),2)*MOD(INT(MOD(INT((E5)/65536),256)/2^4),2)*16+MOD(INT(MOD(INT((D5)/65536),256)/2^5),2)*MOD(INT(MOD(INT((E5)/65536),256)/2^5),2)*32+MOD(INT(MOD(INT((D5)/65536),256)/2^6),2)*MOD(INT(MOD(INT((E5)/65536),256)/2^6),2)*64+MOD(INT(MOD(INT((D5)/65536),256)/2^7),2)*MOD(INT(MOD(INT((E5)/65536),256)/2^7),2)*128)*65536+(MOD(INT(MOD(INT((D5)/16777216),256)/2^0),2)*MOD(INT(MOD(INT((E5)/16777216),256)/2^0),2)*1+MOD(INT(MOD(INT((D5)/16777216),256)/2^1),2)*MOD(INT(MOD(INT((E5)/16777216),256)/2^1),2)*2+MOD(INT(MOD(INT((D5)/16777216),256)/2^2),2)*MOD(INT(MOD(INT((E5)/16777216),256)/2^2),2)*4+MOD(INT(MOD(INT((D5)/16777216),256)/2^3),2)*MOD(INT(MOD(INT((E5)/16777216),256)/2^3),2)*8+MOD(INT(MOD(INT((D5)/16777216),256)/2^4),2)*MOD(INT(MOD(INT((E5)/16777216),256)/2^4),2)*16+MOD(INT(MOD(INT((D5)/16777216),256)/2^5),2)*MOD(INT(MOD(INT((E5)/16777216),256)/2^5),2)*32+MOD(INT(MOD(INT((D5)/16777216),256)/2^6),2)*MOD(INT(MOD(INT((E5)/16777216),256)/2^6),2)*64+MOD(INT(MOD(INT((D5)/16777216),256)/2^7),2)*MOD(INT(MOD(INT((E5)/16777216),256)/2^7),2)*128)*16777216) -> 2290649224 | H6: =((MOD(INT(MOD(INT(((4294967295-D5))/1),256)/2^0),2)*MOD(INT(MOD(INT((F5)/1),256)/2^0),2)*1+MOD(INT(MOD(INT(((4294967295-D5))/1),256)/2^1),2)*MOD(INT(MOD(INT((F5)/1),256)/2^1),2)*2+MOD(INT(MOD(INT(((4294967295-D5))/1),256)/2^2),2)*MOD(INT(MOD(INT((F5)/1),256)/2^2),2)*4+MOD(INT(MOD(INT(((4294967295-D5))/1),256)/2^3),2)*MOD(INT(MOD(INT((F5)/1),256)/2^3),2)*8+MOD(INT(MOD(INT(((4294967295-D5))/1),256)/2^4),2)*MOD(INT(MOD(INT((F5)/1),256)/2^4),2)*16+MOD(INT(MOD(INT(((4294967295-D5))/1),256)/2^5),2)*MOD(INT(MOD(INT((F5)/1),256)/2^5),2)*32+MOD(INT(MOD(INT(((4294967295-D5))/1),256)/2^6),2)*MOD(INT(MOD(INT((F5)/1),256)/2^6),2)*64+MOD(INT(MOD(INT(((4294967295-D5))/1),256)/2^7),2)*MOD(INT(MOD(INT((F5)/1),256)/2^7),2)*128)*1+(MOD(INT(MOD(INT(((4294967295-D5))/256),256)/2^0),2)*MOD(INT(MOD(INT((F5)/256),256)/2^0),2)*1+MOD(INT(MOD(INT(((4294967295-D5))/256),256)/2^1),2)*MOD(INT(MOD(INT((F5)/256),256)/2^1),2)*2+MOD(INT(MOD(INT(((4294967295-D5))/256),256)/2^2),2)*MOD(INT(MOD(INT((F5)/256),256)/2^2),2)*4+MOD(INT(MOD(INT(((4294967295-D5))/256),256)/2^3),2)*MOD(INT(MOD(INT((F5)/256),256)/2^3),2)*8+MOD(INT(MOD(INT(((4294967295-D5))/256),256)/2^4),2)*MOD(INT(MOD(INT((F5)/256),256)/2^4),2)*16+MOD(INT(MOD(INT(((4294967295-D5))/256),256)/2^5),2)*MOD(INT(MOD(INT((F5)/256),256)/2^5),2)*32+MOD(INT(MOD(INT(((4294967295-D5))/256),256)/2^6),2)*MOD(INT(MOD(INT((F5)/256),256)/2^6),2)*64+MOD(INT(MOD(INT(((4294967295-D5))/256),256)/2^7),2)*MOD(INT(MOD(INT((F5)/256),256)/2^7),2)*128)*256+(MOD(INT(MOD(INT(((4294967295-D5))/65536),256)/2^0),2)*MOD(INT(MOD(INT((F5)/65536),256)/2^0),2)*1+MOD(INT(MOD(INT(((4294967295-D5))/65536),256)/2^1),2)*MOD(INT(MOD(INT((F5)/65536),256)/2^1),2)*2+MOD(INT(MOD(INT(((4294967295-D5))/65536),256)/2^2),2)*MOD(INT(MOD(INT((F5)/65536),256)/2^2),2)*4+MOD(INT(MOD(INT(((4294967295-D5))/65536),256)/2^3),2)*MOD(INT(MOD(INT((F5)/65536),256)/2^3),2)*8+MOD(INT(MOD(INT(((4294967295-D5))/65536),256)/2^4),2)*MOD(INT(MOD(INT((F5)/65536),256)/2^4),2)*16+MOD(INT(MOD(INT(((4294967295-D5))/65536),256)/2^5),2)*MOD(INT(MOD(INT((F5)/65536),256)/2^5),2)*32+MOD(INT(MOD(INT(((4294967295-D5))/65536),256)/2^6),2)*MOD(INT(MOD(INT((F5)/65536),256)/2^6),2)*64+MOD(INT(MOD(INT(((4294967295-D5))/65536),256)/2^7),2)*MOD(INT(MOD(INT((F5)/65536),256)/2^7),2)*128)*65536+(MOD(INT(MOD(INT(((4294967295-D5))/16777216),256)/2^0),2)*MOD(INT(MOD(INT((F5)/16777216),256)/2^0),2)*1+MOD(INT(MOD(INT(((4294967295-D5))/16777216),256)/2^1),2)*MOD(INT(MOD(INT((F5)/16777216),256)/2^1),2)*2+MOD(INT(MOD(INT(((4294967295-D5))/16777216),256)/2^2),2)*MOD(INT(MOD(INT((F5)/16777216),256)/2^2),2)*4+MOD(INT(MOD(INT(((4294967295-D5))/16777216),256)/2^3),2)*MOD(INT(MOD(INT((F5)/16777216),256)/2^3),2)*8+MOD(INT(MOD(INT(((4294967295-D5))/16777216),256)/2^4),2)*MOD(INT(MOD(INT((F5)/16777216),256)/2^4),2)*16+MOD(INT(MOD(INT(((4294967295-D5))/16777216),256)/2^5),2)*MOD(INT(MOD(INT((F5)/16777216),256)/2^5),2)*32+MOD(INT(MOD(INT(((4294967295-D5))/16777216),256)/2^6),2)*MOD(INT(MOD(INT((F5)/16777216),256)/2^6),2)*64+MOD(INT(MOD(INT(((4294967295-D5))/16777216),256)/2^7),2)*MOD(INT(MOD(INT((F5)/16777216),256)/2^7),2)*128)*16777216) -> 271733878 | I6: — | J6: =MOD(G6+H6,4294967296) -> 2562383102 | K6: =(IF(LEN('🔐 MD5'!B5)>0,CODE(MID('🔐 MD5'!B5,1,1)),IF(LEN('🔐 MD5'!B5)=0,128,0)))+(IF(LEN('🔐 MD5'!B5)>1,CODE(MID('🔐 MD5'!B5,2,1)),IF(LEN('🔐 MD5'!B5)=1,128,0)))*256+(IF(LEN('🔐 MD5'!B5)>2,CODE(MID('🔐 MD5'!B5,3,1)),IF(LEN('🔐 MD5'!B5)=2,128,0)))*65536+(IF(LEN('🔐 MD5'!B5)>3,CODE(MID('🔐 MD5'!B5,4,1)),IF(LEN('🔐 MD5'!B5)=3,128,0)))*16777216 -> 1819043176 | L6: ='📦 MD5 Constants'!C4 -> 3614090360 | M6: ='📦 MD5 Constants'!H4 -> 7 | N6: =MOD(C5+J6+K6+'📦 MD5 Constants'!C4,4294967296) -> 1138166239 | O6: =MOD(MOD(N6,2^25)*2^7+INT(N6/2^25),4294967296) -> 3951357857 | P6: =D6 -> 3679623978 | Q6: Round 1: F(B,C,D)=AND(B,C)+AND(NOT_B,D)
B7: 2 | C7: =F6 -> 2562383102 | D7: =MOD(D6+O7,4294967296) -> 286529400 | E7: =D6 -> 3679623978 | F7: =E6 -> 4023233417 | G7: =((MOD(INT(MOD(INT((D6)/1),256)/2^0),2)*MOD(INT(MOD(INT((E6)/1),256)/2^0),2)*1+MOD(INT(MOD(INT((D6)/1),256)/2^1),2)*MOD(INT(MOD(INT((E6)/1),256)/2^1),2)*2+MOD(INT(MOD(INT((D6)/1),256)/2^2),2)*MOD(INT(MOD(INT((E6)/1),256)/2^2),2)*4+MOD(INT(MOD(INT((D6)/1),256)/2^3),2)*MOD(INT(MOD(INT((E6)/1),256)/2^3),2)*8+MOD(INT(MOD(INT((D6)/1),256)/2^4),2)*MOD(INT(MOD(INT((E6)/1),256)/2^4),2)*16+MOD(INT(MOD(INT((D6)/1),256)/2^5),2)*MOD(INT(MOD(INT((E6)/1),256)/2^5),2)*32+MOD(INT(MOD(INT((D6)/1),256)/2^6),2)*MOD(INT(MOD(INT((E6)/1),256)/2^6),2)*64+MOD(INT(MOD(INT((D6)/1),256)/2^7),2)*MOD(INT(MOD(INT((E6)/1),256)/2^7),2)*128)*1+(MOD(INT(MOD(INT((D6)/256),256)/2^0),2)*MOD(INT(MOD(INT((E6)/256),256)/2^0),2)*1+MOD(INT(MOD(INT((D6)/256),256)/2^1),2)*MOD(INT(MOD(INT((E6)/256),256)/2^1),2)*2+MOD(INT(MOD(INT((D6)/256),256)/2^2),2)*MOD(INT(MOD(INT((E6)/256),256)/2^2),2)*4+MOD(INT(MOD(INT((D6)/256),256)/2^3),2)*MOD(INT(MOD(INT((E6)/256),256)/2^3),2)*8+MOD(INT(MOD(INT((D6)/256),256)/2^4),2)*MOD(INT(MOD(INT((E6)/256),256)/2^4),2)*16+MOD(INT(MOD(INT((D6)/256),256)/2^5),2)*MOD(INT(MOD(INT((E6)/256),256)/2^5),2)*32+MOD(INT(MOD(INT((D6)/256),256)/2^6),2)*MOD(INT(MOD(INT((E6)/256),256)/2^6),2)*64+MOD(INT(MOD(INT((D6)/256),256)/2^7),2)*MOD(INT(MOD(INT((E6)/256),256)/2^7),2)*128)*256+(MOD(INT(MOD(INT((D6)/65536),256)/2^0),2)*MOD(INT(MOD(INT((E6)/65536),256)/2^0),2)*1+MOD(INT(MOD(INT((D6)/65536),256)/2^1),2)*MOD(INT(MOD(INT((E6)/65536),256)/2^1),2)*2+MOD(INT(MOD(INT((D6)/65536),256)/2^2),2)*MOD(INT(MOD(INT((E6)/65536),256)/2^2),2)*4+MOD(INT(MOD(INT((D6)/65536),256)/2^3),2)*MOD(INT(MOD(INT((E6)/65536),256)/2^3),2)*8+MOD(INT(MOD(INT((D6)/65536),256)/2^4),2)*MOD(INT(MOD(INT((E6)/65536),256)/2^4),2)*16+MOD(INT(MOD(INT((D6)/65536),256)/2^5),2)*MOD(INT(MOD(INT((E6)/65536),256)/2^5),2)*32+MOD(INT(MOD(INT((D6)/65536),256)/2^6),2)*MOD(INT(MOD(INT((E6)/65536),256)/2^6),2)*64+MOD(INT(MOD(INT((D6)/65536),256)/2^7),2)*MOD(INT(MOD(INT((E6)/65536),256)/2^7),2)*128)*65536+(MOD(INT(MOD(INT((D6)/16777216),256)/2^0),2)*MOD(INT(MOD(INT((E6)/16777216),256)/2^0),2)*1+MOD(INT(MOD(INT((D6)/16777216),256)/2^1),2)*MOD(INT(MOD(INT((E6)/16777216),256)/2^1),2)*2+MOD(INT(MOD(INT((D6)/16777216),256)/2^2),2)*MOD(INT(MOD(INT((E6)/16777216),256)/2^2),2)*4+MOD(INT(MOD(INT((D6)/16777216),256)/2^3),2)*MOD(INT(MOD(INT((E6)/16777216),256)/2^3),2)*8+MOD(INT(MOD(INT((D6)/16777216),256)/2^4),2)*MOD(INT(MOD(INT((E6)/16777216),256)/2^4),2)*16+MOD(INT(MOD(INT((D6)/16777216),256)/2^5),2)*MOD(INT(MOD(INT((E6)/16777216),256)/2^5),2)*32+MOD(INT(MOD(INT((D6)/16777216),256)/2^6),2)*MOD(INT(MOD(INT((E6)/16777216),256)/2^6),2)*64+MOD(INT(MOD(INT((D6)/16777216),256)/2^7),2)*MOD(INT(MOD(INT((E6)/16777216),256)/2^7),2)*128)*16777216) -> 3410004744 | H7: =((MOD(INT(MOD(INT(((4294967295-D6))/1),256)/2^0),2)*MOD(INT(MOD(INT((F6)/1),256)/2^0),2)*1+MOD(INT(MOD(INT(((4294967295-D6))/1),256)/2^1),2)*MOD(INT(MOD(INT((F6)/1),256)/2^1),2)*2+MOD(INT(MOD(INT(((4294967295-D6))/1),256)/2^2),2)*MOD(INT(MOD(INT((F6)/1),256)/2^2),2)*4+MOD(INT(MOD(INT(((4294967295-D6))/1),256)/2^3),2)*MOD(INT(MOD(INT((F6)/1),256)/2^3),2)*8+MOD(INT(MOD(INT(((4294967295-D6))/1),256)/2^4),2)*MOD(INT(MOD(INT((F6)/1),256)/2^4),2)*16+MOD(INT(MOD(INT(((4294967295-D6))/1),256)/2^5),2)*MOD(INT(MOD(INT((F6)/1),256)/2^5),2)*32+MOD(INT(MOD(INT(((4294967295-D6))/1),256)/2^6),2)*MOD(INT(MOD(INT((F6)/1),256)/2^6),2)*64+MOD(INT(MOD(INT(((4294967295-D6))/1),256)/2^7),2)*MOD(INT(MOD(INT((F6)/1),256)/2^7),2)*128)*1+(MOD(INT(MOD(INT(((4294967295-D6))/256),256)/2^0),2)*MOD(INT(MOD(INT((F6)/256),256)/2^0),2)*1+MOD(INT(MOD(INT(((4294967295-D6))/256),256)/2^1),2)*MOD(INT(MOD(INT((F6)/256),256)/2^1),2)*2+MOD(INT(MOD(INT(((4294967295-D6))/256),256)/2^2),2)*MOD(INT(MOD(INT((F6)/256),256)/2^2),2)*4+MOD(INT(MOD(INT(((4294967295-D6))/256),256)/2^3),2)*MOD(INT(MOD(INT((F6)/256),256)/2^3),2)*8+MOD(INT(MOD(INT(((4294967295-D6))/256),256)/2^4),2)*MOD(INT(MOD(INT((F6)/256),256)/2^4),2)*16+MOD(INT(MOD(INT(((4294967295-D6))/256),256)/2^5),2)*MOD(INT(MOD(INT((F6)/256),256)/2^5),2)*32+MOD(INT(MOD(INT(((4294967295-D6))/256),256)/2^6),2)*MOD(INT(MOD(INT((F6)/256),256)/2^6),2)*64+MOD(INT(MOD(INT(((4294967295-D6))/256),256)/2^7),2)*MOD(INT(MOD(INT((F6)/256),256)/2^7),2)*128)*256+(MOD(INT(MOD(INT(((4294967295-D6))/65536),256)/2^0),2)*MOD(INT(MOD(INT((F6)/65536),256)/2^0),2)*1+MOD(INT(MOD(INT(((4294967295-D6))/65536),256)/2^1),2)*MOD(INT(MOD(INT((F6)/65536),256)/2^1),2)*2+MOD(INT(MOD(INT(((4294967295-D6))/65536),256)/2^2),2)*MOD(INT(MOD(INT((F6)/65536),256)/2^2),2)*4+MOD(INT(MOD(INT(((4294967295-D6))/65536),256)/2^3),2)*MOD(INT(MOD(INT((F6)/65536),256)/2^3),2)*8+MOD(INT(MOD(INT(((4294967295-D6))/65536),256)/2^4),2)*MOD(INT(MOD(INT((F6)/65536),256)/2^4),2)*16+MOD(INT(MOD(INT(((4294967295-D6))/65536),256)/2^5),2)*MOD(INT(MOD(INT((F6)/65536),256)/2^5),2)*32+MOD(INT(MOD(INT(((4294967295-D6))/65536),256)/2^6),2)*MOD(INT(MOD(INT((F6)/65536),256)/2^6),2)*64+MOD(INT(MOD(INT(((4294967295-D6))/65536),256)/2^7),2)*MOD(INT(MOD(INT((F6)/65536),256)/2^7),2)*128)*65536+(MOD(INT(MOD(INT(((4294967295-D6))/16777216),256)/2^0),2)*MOD(INT(MOD(INT((F6)/16777216),256)/2^0),2)*1+MOD(INT(MOD(INT(((4294967295-D6))/16777216),256)/2^1),2)*MOD(INT(MOD(INT((F6)/16777216),256)/2^1),2)*2+MOD(INT(MOD(INT(((4294967295-D6))/16777216),256)/2^2),2)*MOD(INT(MOD(INT((F6)/16777216),256)/2^2),2)*4+MOD(INT(MOD(INT(((4294967295-D6))/16777216),256)/2^3),2)*MOD(INT(MOD(INT((F6)/16777216),256)/2^3),2)*8+MOD(INT(MOD(INT(((4294967295-D6))/16777216),256)/2^4),2)*MOD(INT(MOD(INT((F6)/16777216),256)/2^4),2)*16+MOD(INT(MOD(INT(((4294967295-D6))/16777216),256)/2^5),2)*MOD(INT(MOD(INT((F6)/16777216),256)/2^5),2)*32+MOD(INT(MOD(INT(((4294967295-D6))/16777216),256)/2^6),2)*MOD(INT(MOD(INT((F6)/16777216),256)/2^6),2)*64+MOD(INT(MOD(INT(((4294967295-D6))/16777216),256)/2^7),2)*MOD(INT(MOD(INT((F6)/16777216),256)/2^7),2)*128)*16777216) -> 11027668 | I7: — | J7: =MOD(G7+H7,4294967296) -> 3421032412 | K7: =(IF(LEN('🔐 MD5'!B5)>4,CODE(MID('🔐 MD5'!B5,5,1)),IF(LEN('🔐 MD5'!B5)=4,128,0)))+(IF(LEN('🔐 MD5'!B5)>5,CODE(MID('🔐 MD5'!B5,6,1)),IF(LEN('🔐 MD5'!B5)=5,128,0)))*256+(IF(LEN('🔐 MD5'!B5)>6,CODE(MID('🔐 MD5'!B5,7,1)),IF(LEN('🔐 MD5'!B5)=6,128,0)))*65536+(IF(LEN('🔐 MD5'!B5)=7,128,0))*16777216 -> 32879 | L7: ='📦 MD5 Constants'!C5 -> 3905402710 | M7: ='📦 MD5 Constants'!H5 -> 12 | N7: =MOD(C6+J7+K7+'📦 MD5 Constants'!C5,4294967296) -> 3303234583 | O7: =MOD(MOD(N7,2^20)*2^12+INT(N7/2^20),4294967296) -> 901872718 | P7: =D7 -> 286529400 | Q7: op=2 g=M[1] shift=12
B8: 3 | C8: =F7 -> 4023233417 | D8: =MOD(D7+O8,4294967296) -> 605655266 | E8: =D7 -> 286529400 | F8: =E7 -> 3679623978 | G8: =((MOD(INT(MOD(INT((D7)/1),256)/2^0),2)*MOD(INT(MOD(INT((E7)/1),256)/2^0),2)*1+MOD(INT(MOD(INT((D7)/1),256)/2^1),2)*MOD(INT(MOD(INT((E7)/1),256)/2^1),2)*2+MOD(INT(MOD(INT((D7)/1),256)/2^2),2)*MOD(INT(MOD(INT((E7)/1),256)/2^2),2)*4+MOD(INT(MOD(INT((D7)/1),256)/2^3),2)*MOD(INT(MOD(INT((E7)/1),256)/2^3),2)*8+MOD(INT(MOD(INT((D7)/1),256)/2^4),2)*MOD(INT(MOD(INT((E7)/1),256)/2^4),2)*16+MOD(INT(MOD(INT((D7)/1),256)/2^5),2)*MOD(INT(MOD(INT((E7)/1),256)/2^5),2)*32+MOD(INT(MOD(INT((D7)/1),256)/2^6),2)*MOD(INT(MOD(INT((E7)/1),256)/2^6),2)*64+MOD(INT(MOD(INT((D7)/1),256)/2^7),2)*MOD(INT(MOD(INT((E7)/1),256)/2^7),2)*128)*1+(MOD(INT(MOD(INT((D7)/256),256)/2^0),2)*MOD(INT(MOD(INT((E7)/256),256)/2^0),2)*1+MOD(INT(MOD(INT((D7)/256),256)/2^1),2)*MOD(INT(MOD(INT((E7)/256),256)/2^1),2)*2+MOD(INT(MOD(INT((D7)/256),256)/2^2),2)*MOD(INT(MOD(INT((E7)/256),256)/2^2),2)*4+MOD(INT(MOD(INT((D7)/256),256)/2^3),2)*MOD(INT(MOD(INT((E7)/256),256)/2^3),2)*8+MOD(INT(MOD(INT((D7)/256),256)/2^4),2)*MOD(INT(MOD(INT((E7)/256),256)/2^4),2)*16+MOD(INT(MOD(INT((D7)/256),256)/2^5),2)*MOD(INT(MOD(INT((E7)/256),256)/2^5),2)*32+MOD(INT(MOD(INT((D7)/256),256)/2^6),2)*MOD(INT(MOD(INT((E7)/256),256)/2^6),2)*64+MOD(INT(MOD(INT((D7)/256),256)/2^7),2)*MOD(INT(MOD(INT((E7)/256),256)/2^7),2)*128)*256+(MOD(INT(MOD(INT((D7)/65536),256)/2^0),2)*MOD(INT(MOD(INT((E7)/65536),256)/2^0),2)*1+MOD(INT(MOD(INT((D7)/65536),256)/2^1),2)*MOD(INT(MOD(INT((E7)/65536),256)/2^1),2)*2+MOD(INT(MOD(INT((D7)/65536),256)/2^2),2)*MOD(INT(MOD(INT((E7)/65536),256)/2^2),2)*4+MOD(INT(MOD(INT((D7)/65536),256)/2^3),2)*MOD(INT(MOD(INT((E7)/65536),256)/2^3),2)*8+MOD(INT(MOD(INT((D7)/65536),256)/2^4),2)*MOD(INT(MOD(INT((E7)/65536),256)/2^4),2)*16+MOD(INT(MOD(INT((D7)/65536),256)/2^5),2)*MOD(INT(MOD(INT((E7)/65536),256)/2^5),2)*32+MOD(INT(MOD(INT((D7)/65536),256)/2^6),2)*MOD(INT(MOD(INT((E7)/65536),256)/2^6),2)*64+MOD(INT(MOD(INT((D7)/65536),256)/2^7),2)*MOD(INT(MOD(INT((E7)/65536),256)/2^7),2)*128)*65536+(MOD(INT(MOD(INT((D7)/16777216),256)/2^0),2)*MOD(INT(MOD(INT((E7)/16777216),256)/2^0),2)*1+MOD(INT(MOD(INT((D7)/16777216),256)/2^1),2)*MOD(INT(MOD(INT((E7)/16777216),256)/2^1),2)*2+MOD(INT(MOD(INT((D7)/16777216),256)/2^2),2)*MOD(INT(MOD(INT((E7)/16777216),256)/2^2),2)*4+MOD(INT(MOD(INT((D7)/16777216),256)/2^3),2)*MOD(INT(MOD(INT((E7)/16777216),256)/2^3),2)*8+MOD(INT(MOD(INT((D7)/16777216),256)/2^4),2)*MOD(INT(MOD(INT((E7)/16777216),256)/2^4),2)*16+MOD(INT(MOD(INT((D7)/16777216),256)/2^5),2)*MOD(INT(MOD(INT((E7)/16777216),256)/2^5),2)*32+MOD(INT(MOD(INT((D7)/16777216),256)/2^6),2)*MOD(INT(MOD(INT((E7)/16777216),256)/2^6),2)*64+MOD(INT(MOD(INT((D7)/16777216),256)/2^7),2)*MOD(INT(MOD(INT((E7)/16777216),256)/2^7),2)*128)*16777216) -> 286266152 | H8: =((MOD(INT(MOD(INT(((4294967295-D7))/1),256)/2^0),2)*MOD(INT(MOD(INT((F7)/1),256)/2^0),2)*1+MOD(INT(MOD(INT(((4294967295-D7))/1),256)/2^1),2)*MOD(INT(MOD(INT((F7)/1),256)/2^1),2)*2+MOD(INT(MOD(INT(((4294967295-D7))/1),256)/2^2),2)*MOD(INT(MOD(INT((F7)/1),256)/2^2),2)*4+MOD(INT(MOD(INT(((4294967295-D7))/1),256)/2^3),2)*MOD(INT(MOD(INT((F7)/1),256)/2^3),2)*8+MOD(INT(MOD(INT(((4294967295-D7))/1),256)/2^4),2)*MOD(INT(MOD(INT((F7)/1),256)/2^4),2)*16+MOD(INT(MOD(INT(((4294967295-D7))/1),256)/2^5),2)*MOD(INT(MOD(INT((F7)/1),256)/2^5),2)*32+MOD(INT(MOD(INT(((4294967295-D7))/1),256)/2^6),2)*MOD(INT(MOD(INT((F7)/1),256)/2^6),2)*64+MOD(INT(MOD(INT(((4294967295-D7))/1),256)/2^7),2)*MOD(INT(MOD(INT((F7)/1),256)/2^7),2)*128)*1+(MOD(INT(MOD(INT(((4294967295-D7))/256),256)/2^0),2)*MOD(INT(MOD(INT((F7)/256),256)/2^0),2)*1+MOD(INT(MOD(INT(((4294967295-D7))/256),256)/2^1),2)*MOD(INT(MOD(INT((F7)/256),256)/2^1),2)*2+MOD(INT(MOD(INT(((4294967295-D7))/256),256)/2^2),2)*MOD(INT(MOD(INT((F7)/256),256)/2^2),2)*4+MOD(INT(MOD(INT(((4294967295-D7))/256),256)/2^3),2)*MOD(INT(MOD(INT((F7)/256),256)/2^3),2)*8+MOD(INT(MOD(INT(((4294967295-D7))/256),256)/2^4),2)*MOD(INT(MOD(INT((F7)/256),256)/2^4),2)*16+MOD(INT(MOD(INT(((4294967295-D7))/256),256)/2^5),2)*MOD(INT(MOD(INT((F7)/256),256)/2^5),2)*32+MOD(INT(MOD(INT(((4294967295-D7))/256),256)/2^6),2)*MOD(INT(MOD(INT((F7)/256),256)/2^6),2)*64+MOD(INT(MOD(INT(((4294967295-D7))/256),256)/2^7),2)*MOD(INT(MOD(INT((F7)/256),256)/2^7),2)*128)*256+(MOD(INT(MOD(INT(((4294967295-D7))/65536),256)/2^0),2)*MOD(INT(MOD(INT((F7)/65536),256)/2^0),2)*1+MOD(INT(MOD(INT(((4294967295-D7))/65536),256)/2^1),2)*MOD(INT(MOD(INT((F7)/65536),256)/2^1),2)*2+MOD(INT(MOD(INT(((4294967295-D7))/65536),256)/2^2),2)*MOD(INT(MOD(INT((F7)/65536),256)/2^2),2)*4+MOD(INT(MOD(INT(((4294967295-D7))/65536),256)/2^3),2)*MOD(INT(MOD(INT((F7)/65536),256)/2^3),2)*8+MOD(INT(MOD(INT(((4294967295-D7))/65536),256)/2^4),2)*MOD(INT(MOD(INT((F7)/65536),256)/2^4),2)*16+MOD(INT(MOD(INT(((4294967295-D7))/65536),256)/2^5),2)*MOD(INT(MOD(INT((F7)/65536),256)/2^5),2)*32+MOD(INT(MOD(INT(((4294967295-D7))/65536),256)/2^6),2)*MOD(INT(MOD(INT((F7)/65536),256)/2^6),2)*64+MOD(INT(MOD(INT(((4294967295-D7))/65536),256)/2^7),2)*MOD(INT(MOD(INT((F7)/65536),256)/2^7),2)*128)*65536+(MOD(INT(MOD(INT(((4294967295-D7))/16777216),256)/2^0),2)*MOD(INT(MOD(INT((F7)/16777216),256)/2^0),2)*1+MOD(INT(MOD(INT(((4294967295-D7))/16777216),256)/2^1),2)*MOD(INT(MOD(INT((F7)/16777216),256)/2^1),2)*2+MOD(INT(MOD(INT(((4294967295-D7))/16777216),256)/2^2),2)*MOD(INT(MOD(INT((F7)/16777216),256)/2^2),2)*4+MOD(INT(MOD(INT(((4294967295-D7))/16777216),256)/2^3),2)*MOD(INT(MOD(INT((F7)/16777216),256)/2^3),2)*8+MOD(INT(MOD(INT(((4294967295-D7))/16777216),256)/2^4),2)*MOD(INT(MOD(INT((F7)/16777216),256)/2^4),2)*16+MOD(INT(MOD(INT(((4294967295-D7))/16777216),256)/2^5),2)*MOD(INT(MOD(INT((F7)/16777216),256)/2^5),2)*32+MOD(INT(MOD(INT(((4294967295-D7))/16777216),256)/2^6),2)*MOD(INT(MOD(INT((F7)/16777216),256)/2^6),2)*64+MOD(INT(MOD(INT(((4294967295-D7))/16777216),256)/2^7),2)*MOD(INT(MOD(INT((F7)/16777216),256)/2^7),2)*128)*16777216) -> 4006193281 | I8: — | J8: =MOD(G8+H8,4294967296) -> 4292459433 | K8: =(0)+(0)*256+(0)*65536+(0)*16777216 -> 0 | L8: ='📦 MD5 Constants'!C6 -> 606105819 | M8: ='📦 MD5 Constants'!H6 -> 17 | N8: =MOD(C7+J8+K8+'📦 MD5 Constants'!C6,4294967296) -> 3165981058 | O8: =MOD(MOD(N8,2^15)*2^17+INT(N8/2^15),4294967296) -> 319125866 | P8: =D8 -> 605655266 | Q8: op=3 g=M[2] shift=17
B9: 4 | C9: =F8 -> 3679623978 | D9: =MOD(D8+O9,4294967296) -> 2617034823 | E9: =D8 -> 605655266 | F9: =E8 -> 286529400 | G9: =((MOD(INT(MOD(INT((D8)/1),256)/2^0),2)*MOD(INT(MOD(INT((E8)/1),256)/2^0),2)*1+MOD(INT(MOD(INT((D8)/1),256)/2^1),2)*MOD(INT(MOD(INT((E8)/1),256)/2^1),2)*2+MOD(INT(MOD(INT((D8)/1),256)/2^2),2)*MOD(INT(MOD(INT((E8)/1),256)/2^2),2)*4+MOD(INT(MOD(INT((D8)/1),256)/2^3),2)*MOD(INT(MOD(INT((E8)/1),256)/2^3),2)*8+MOD(INT(MOD(INT((D8)/1),256)/2^4),2)*MOD(INT(MOD(INT((E8)/1),256)/2^4),2)*16+MOD(INT(MOD(INT((D8)/1),256)/2^5),2)*MOD(INT(MOD(INT((E8)/1),256)/2^5),2)*32+MOD(INT(MOD(INT((D8)/1),256)/2^6),2)*MOD(INT(MOD(INT((E8)/1),256)/2^6),2)*64+MOD(INT(MOD(INT((D8)/1),256)/2^7),2)*MOD(INT(MOD(INT((E8)/1),256)/2^7),2)*128)*1+(MOD(INT(MOD(INT((D8)/256),256)/2^0),2)*MOD(INT(MOD(INT((E8)/256),256)/2^0),2)*1+MOD(INT(MOD(INT((D8)/256),256)/2^1),2)*MOD(INT(MOD(INT((E8)/256),256)/2^1),2)*2+MOD(INT(MOD(INT((D8)/256),256)/2^2),2)*MOD(INT(MOD(INT((E8)/256),256)/2^2),2)*4+MOD(INT(MOD(INT((D8)/256),256)/2^3),2)*MOD(INT(MOD(INT((E8)/256),256)/2^3),2)*8+MOD(INT(MOD(INT((D8)/256),256)/2^4),2)*MOD(INT(MOD(INT((E8)/256),256)/2^4),2)*16+MOD(INT(MOD(INT((D8)/256),256)/2^5),2)*MOD(INT(MOD(INT((E8)/256),256)/2^5),2)*32+MOD(INT(MOD(INT((D8)/256),256)/2^6),2)*MOD(INT(MOD(INT((E8)/256),256)/2^6),2)*64+MOD(INT(MOD(INT((D8)/256),256)/2^7),2)*MOD(INT(MOD(INT((E8)/256),256)/2^7),2)*128)*256+(MOD(INT(MOD(INT((D8)/65536),256)/2^0),2)*MOD(INT(MOD(INT((E8)/65536),256)/2^0),2)*1+MOD(INT(MOD(INT((D8)/65536),256)/2^1),2)*MOD(INT(MOD(INT((E8)/65536),256)/2^1),2)*2+MOD(INT(MOD(INT((D8)/65536),256)/2^2),2)*MOD(INT(MOD(INT((E8)/65536),256)/2^2),2)*4+MOD(INT(MOD(INT((D8)/65536),256)/2^3),2)*MOD(INT(MOD(INT((E8)/65536),256)/2^3),2)*8+MOD(INT(MOD(INT((D8)/65536),256)/2^4),2)*MOD(INT(MOD(INT((E8)/65536),256)/2^4),2)*16+MOD(INT(MOD(INT((D8)/65536),256)/2^5),2)*MOD(INT(MOD(INT((E8)/65536),256)/2^5),2)*32+MOD(INT(MOD(INT((D8)/65536),256)/2^6),2)*MOD(INT(MOD(INT((E8)/65536),256)/2^6),2)*64+MOD(INT(MOD(INT((D8)/65536),256)/2^7),2)*MOD(INT(MOD(INT((E8)/65536),256)/2^7),2)*128)*65536+(MOD(INT(MOD(INT((D8)/16777216),256)/2^0),2)*MOD(INT(MOD(INT((E8)/16777216),256)/2^0),2)*1+MOD(INT(MOD(INT((D8)/16777216),256)/2^1),2)*MOD(INT(MOD(INT((E8)/16777216),256)/2^1),2)*2+MOD(INT(MOD(INT((D8)/16777216),256)/2^2),2)*MOD(INT(MOD(INT((E8)/16777216),256)/2^2),2)*4+MOD(INT(MOD(INT((D8)/16777216),256)/2^3),2)*MOD(INT(MOD(INT((E8)/16777216),256)/2^3),2)*8+MOD(INT(MOD(INT((D8)/16777216),256)/2^4),2)*MOD(INT(MOD(INT((E8)/16777216),256)/2^4),2)*16+MOD(INT(MOD(INT((D8)/16777216),256)/2^5),2)*MOD(INT(MOD(INT((E8)/16777216),256)/2^5),2)*32+MOD(INT(MOD(INT((D8)/16777216),256)/2^6),2)*MOD(INT(MOD(INT((E8)/16777216),256)/2^6),2)*64+MOD(INT(MOD(INT((D8)/16777216),256)/2^7),2)*MOD(INT(MOD(INT((E8)/16777216),256)/2^7),2)*128)*16777216) -> 1052768 | H9: =((MOD(INT(MOD(INT(((4294967295-D8))/1),256)/2^0),2)*MOD(INT(MOD(INT((F8)/1),256)/2^0),2)*1+MOD(INT(MOD(INT(((4294967295-D8))/1),256)/2^1),2)*MOD(INT(MOD(INT((F8)/1),256)/2^1),2)*2+MOD(INT(MOD(INT(((4294967295-D8))/1),256)/2^2),2)*MOD(INT(MOD(INT((F8)/1),256)/2^2),2)*4+MOD(INT(MOD(INT(((4294967295-D8))/1),256)/2^3),2)*MOD(INT(MOD(INT((F8)/1),256)/2^3),2)*8+MOD(INT(MOD(INT(((4294967295-D8))/1),256)/2^4),2)*MOD(INT(MOD(INT((F8)/1),256)/2^4),2)*16+MOD(INT(MOD(INT(((4294967295-D8))/1),256)/2^5),2)*MOD(INT(MOD(INT((F8)/1),256)/2^5),2)*32+MOD(INT(MOD(INT(((4294967295-D8))/1),256)/2^6),2)*MOD(INT(MOD(INT((F8)/1),256)/2^6),2)*64+MOD(INT(MOD(INT(((4294967295-D8))/1),256)/2^7),2)*MOD(INT(MOD(INT((F8)/1),256)/2^7),2)*128)*1+(MOD(INT(MOD(INT(((4294967295-D8))/256),256)/2^0),2)*MOD(INT(MOD(INT((F8)/256),256)/2^0),2)*1+MOD(INT(MOD(INT(((4294967295-D8))/256),256)/2^1),2)*MOD(INT(MOD(INT((F8)/256),256)/2^1),2)*2+MOD(INT(MOD(INT(((4294967295-D8))/256),256)/2^2),2)*MOD(INT(MOD(INT((F8)/256),256)/2^2),2)*4+MOD(INT(MOD(INT(((4294967295-D8))/256),256)/2^3),2)*MOD(INT(MOD(INT((F8)/256),256)/2^3),2)*8+MOD(INT(MOD(INT(((4294967295-D8))/256),256)/2^4),2)*MOD(INT(MOD(INT((F8)/256),256)/2^4),2)*16+MOD(INT(MOD(INT(((4294967295-D8))/256),256)/2^5),2)*MOD(INT(MOD(INT((F8)/256),256)/2^5),2)*32+MOD(INT(MOD(INT(((4294967295-D8))/256),256)/2^6),2)*MOD(INT(MOD(INT((F8)/256),256)/2^6),2)*64+MOD(INT(MOD(INT(((4294967295-D8))/256),256)/2^7),2)*MOD(INT(MOD(INT((F8)/256),256)/2^7),2)*128)*256+(MOD(INT(MOD(INT(((4294967295-D8))/65536),256)/2^0),2)*MOD(INT(MOD(INT((F8)/65536),256)/2^0),2)*1+MOD(INT(MOD(INT(((4294967295-D8))/65536),256)/2^1),2)*MOD(INT(MOD(INT((F8)/65536),256)/2^1),2)*2+MOD(INT(MOD(INT(((4294967295-D8))/65536),256)/2^2),2)*MOD(INT(MOD(INT((F8)/65536),256)/2^2),2)*4+MOD(INT(MOD(INT(((4294967295-D8))/65536),256)/2^3),2)*MOD(INT(MOD(INT((F8)/65536),256)/2^3),2)*8+MOD(INT(MOD(INT(((4294967295-D8))/65536),256)/2^4),2)*MOD(INT(MOD(INT((F8)/65536),256)/2^4),2)*16+MOD(INT(MOD(INT(((4294967295-D8))/65536),256)/2^5),2)*MOD(INT(MOD(INT((F8)/65536),256)/2^5),2)*32+MOD(INT(MOD(INT(((4294967295-D8))/65536),256)/2^6),2)*MOD(INT(MOD(INT((F8)/65536),256)/2^6),2)*64+MOD(INT(MOD(INT(((4294967295-D8))/65536),256)/2^7),2)*MOD(INT(MOD(INT((F8)/65536),256)/2^7),2)*128)*65536+(MOD(INT(MOD(INT(((4294967295-D8))/16777216),256)/2^0),2)*MOD(INT(MOD(INT((F8)/16777216),256)/2^0),2)*1+MOD(INT(MOD(INT(((4294967295-D8))/16777216),256)/2^1),2)*MOD(INT(MOD(INT((F8)/16777216),256)/2^1),2)*2+MOD(INT(MOD(INT(((4294967295-D8))/16777216),256)/2^2),2)*MOD(INT(MOD(INT((F8)/16777216),256)/2^2),2)*4+MOD(INT(MOD(INT(((4294967295-D8))/16777216),256)/2^3),2)*MOD(INT(MOD(INT((F8)/16777216),256)/2^3),2)*8+MOD(INT(MOD(INT(((4294967295-D8))/16777216),256)/2^4),2)*MOD(INT(MOD(INT((F8)/16777216),256)/2^4),2)*16+MOD(INT(MOD(INT(((4294967295-D8))/16777216),256)/2^5),2)*MOD(INT(MOD(INT((F8)/16777216),256)/2^5),2)*32+MOD(INT(MOD(INT(((4294967295-D8))/16777216),256)/2^6),2)*MOD(INT(MOD(INT((F8)/16777216),256)/2^6),2)*64+MOD(INT(MOD(INT(((4294967295-D8))/16777216),256)/2^7),2)*MOD(INT(MOD(INT((F8)/16777216),256)/2^7),2)*128)*16777216) -> 3678538504 | I9: — | J9: =MOD(G9+H9,4294967296) -> 3679591272 | K9: =(0)+(0)*256+(0)*65536+(0)*16777216 -> 0 | L9: ='📦 MD5 Constants'!C7 -> 3250441966 | M9: ='📦 MD5 Constants'!H7 -> 22 | N9: =MOD(C8+J9+K9+'📦 MD5 Constants'!C7,4294967296) -> 2363332063 | O9: =MOD(MOD(N9,2^10)*2^22+INT(N9/2^10),4294967296) -> 2011379557 | P9: =D9 -> 2617034823 | Q9: op=4 g=M[3] shift=22
B10: 5 | C10: =F9 -> 286529400 | D10: =MOD(D9+O10,4294967296) -> 262009391 | E10: =D9 -> 2617034823 | F10: =E9 -> 605655266 | G10: =((MOD(INT(MOD(INT((D9)/1),256)/2^0),2)*MOD(INT(MOD(INT((E9)/1),256)/2^0),2)*1+MOD(INT(MOD(INT((D9)/1),256)/2^1),2)*MOD(INT(MOD(INT((E9)/1),256)/2^1),2)*2+MOD(INT(MOD(INT((D9)/1),256)/2^2),2)*MOD(INT(MOD(INT((E9)/1),256)/2^2),2)*4+MOD(INT(MOD(INT((D9)/1),256)/2^3),2)*MOD(INT(MOD(INT((E9)/1),256)/2^3),2)*8+MOD(INT(MOD(INT((D9)/1),256)/2^4),2)*MOD(INT(MOD(INT((E9)/1),256)/2^4),2)*16+MOD(INT(MOD(INT((D9)/1),256)/2^5),2)*MOD(INT(MOD(INT((E9)/1),256)/2^5),2)*32+MOD(INT(MOD(INT((D9)/1),256)/2^6),2)*MOD(INT(MOD(INT((E9)/1),256)/2^6),2)*64+MOD(INT(MOD(INT((D9)/1),256)/2^7),2)*MOD(INT(MOD(INT((E9)/1),256)/2^7),2)*128)*1+(MOD(INT(MOD(INT((D9)/256),256)/2^0),2)*MOD(INT(MOD(INT((E9)/256),256)/2^0),2)*1+MOD(INT(MOD(INT((D9)/256),256)/2^1),2)*MOD(INT(MOD(INT((E9)/256),256)/2^1),2)*2+MOD(INT(MOD(INT((D9)/256),256)/2^2),2)*MOD(INT(MOD(INT((E9)/256),256)/2^2),2)*4+MOD(INT(MOD(INT((D9)/256),256)/2^3),2)*MOD(INT(MOD(INT((E9)/256),256)/2^3),2)*8+MOD(INT(MOD(INT((D9)/256),256)/2^4),2)*MOD(INT(MOD(INT((E9)/256),256)/2^4),2)*16+MOD(INT(MOD(INT((D9)/256),256)/2^5),2)*MOD(INT(MOD(INT((E9)/256),256)/2^5),2)*32+MOD(INT(MOD(INT((D9)/256),256)/2^6),2)*MOD(INT(MOD(INT((E9)/256),256)/2^6),2)*64+MOD(INT(MOD(INT((D9)/256),256)/2^7),2)*MOD(INT(MOD(INT((E9)/256),256)/2^7),2)*128)*256+(MOD(INT(MOD(INT((D9)/65536),256)/2^0),2)*MOD(INT(MOD(INT((E9)/65536),256)/2^0),2)*1+MOD(INT(MOD(INT((D9)/65536),256)/2^1),2)*MOD(INT(MOD(INT((E9)/65536),256)/2^1),2)*2+MOD(INT(MOD(INT((D9)/65536),256)/2^2),2)*MOD(INT(MOD(INT((E9)/65536),256)/2^2),2)*4+MOD(INT(MOD(INT((D9)/65536),256)/2^3),2)*MOD(INT(MOD(INT((E9)/65536),256)/2^3),2)*8+MOD(INT(MOD(INT((D9)/65536),256)/2^4),2)*MOD(INT(MOD(INT((E9)/65536),256)/2^4),2)*16+MOD(INT(MOD(INT((D9)/65536),256)/2^5),2)*MOD(INT(MOD(INT((E9)/65536),256)/2^5),2)*32+MOD(INT(MOD(INT((D9)/65536),256)/2^6),2)*MOD(INT(MOD(INT((E9)/65536),256)/2^6),2)*64+MOD(INT(MOD(INT((D9)/65536),256)/2^7),2)*MOD(INT(MOD(INT((E9)/65536),256)/2^7),2)*128)*65536+(MOD(INT(MOD(INT((D9)/16777216),256)/2^0),2)*MOD(INT(MOD(INT((E9)/16777216),256)/2^0),2)*1+MOD(INT(MOD(INT((D9)/16777216),256)/2^1),2)*MOD(INT(MOD(INT((E9)/16777216),256)/2^1),2)*2+MOD(INT(MOD(INT((D9)/16777216),256)/2^2),2)*MOD(INT(MOD(INT((E9)/16777216),256)/2^2),2)*4+MOD(INT(MOD(INT((D9)/16777216),256)/2^3),2)*MOD(INT(MOD(INT((E9)/16777216),256)/2^3),2)*8+MOD(INT(MOD(INT((D9)/16777216),256)/2^4),2)*MOD(INT(MOD(INT((E9)/16777216),256)/2^4),2)*16+MOD(INT(MOD(INT((D9)/16777216),256)/2^5),2)*MOD(INT(MOD(INT((E9)/16777216),256)/2^5),2)*32+MOD(INT(MOD(INT((D9)/16777216),256)/2^6),2)*MOD(INT(MOD(INT((E9)/16777216),256)/2^6),2)*64+MOD(INT(MOD(INT((D9)/16777216),256)/2^7),2)*MOD(INT(MOD(INT((E9)/16777216),256)/2^7),2)*128)*16777216) -> 1605698 | H10: =((MOD(INT(MOD(INT(((4294967295-D9))/1),256)/2^0),2)*MOD(INT(MOD(INT((F9)/1),256)/2^0),2)*1+MOD(INT(MOD(INT(((4294967295-D9))/1),256)/2^1),2)*MOD(INT(MOD(INT((F9)/1),256)/2^1),2)*2+MOD(INT(MOD(INT(((4294967295-D9))/1),256)/2^2),2)*MOD(INT(MOD(INT((F9)/1),256)/2^2),2)*4+MOD(INT(MOD(INT(((4294967295-D9))/1),256)/2^3),2)*MOD(INT(MOD(INT((F9)/1),256)/2^3),2)*8+MOD(INT(MOD(INT(((4294967295-D9))/1),256)/2^4),2)*MOD(INT(MOD(INT((F9)/1),256)/2^4),2)*16+MOD(INT(MOD(INT(((4294967295-D9))/1),256)/2^5),2)*MOD(INT(MOD(INT((F9)/1),256)/2^5),2)*32+MOD(INT(MOD(INT(((4294967295-D9))/1),256)/2^6),2)*MOD(INT(MOD(INT((F9)/1),256)/2^6),2)*64+MOD(INT(MOD(INT(((4294967295-D9))/1),256)/2^7),2)*MOD(INT(MOD(INT((F9)/1),256)/2^7),2)*128)*1+(MOD(INT(MOD(INT(((4294967295-D9))/256),256)/2^0),2)*MOD(INT(MOD(INT((F9)/256),256)/2^0),2)*1+MOD(INT(MOD(INT(((4294967295-D9))/256),256)/2^1),2)*MOD(INT(MOD(INT((F9)/256),256)/2^1),2)*2+MOD(INT(MOD(INT(((4294967295-D9))/256),256)/2^2),2)*MOD(INT(MOD(INT((F9)/256),256)/2^2),2)*4+MOD(INT(MOD(INT(((4294967295-D9))/256),256)/2^3),2)*MOD(INT(MOD(INT((F9)/256),256)/2^3),2)*8+MOD(INT(MOD(INT(((4294967295-D9))/256),256)/2^4),2)*MOD(INT(MOD(INT((F9)/256),256)/2^4),2)*16+MOD(INT(MOD(INT(((4294967295-D9))/256),256)/2^5),2)*MOD(INT(MOD(INT((F9)/256),256)/2^5),2)*32+MOD(INT(MOD(INT(((4294967295-D9))/256),256)/2^6),2)*MOD(INT(MOD(INT((F9)/256),256)/2^6),2)*64+MOD(INT(MOD(INT(((4294967295-D9))/256),256)/2^7),2)*MOD(INT(MOD(INT((F9)/256),256)/2^7),2)*128)*256+(MOD(INT(MOD(INT(((4294967295-D9))/65536),256)/2^0),2)*MOD(INT(MOD(INT((F9)/65536),256)/2^0),2)*1+MOD(INT(MOD(INT(((4294967295-D9))/65536),256)/2^1),2)*MOD(INT(MOD(INT((F9)/65536),256)/2^1),2)*2+MOD(INT(MOD(INT(((4294967295-D9))/65536),256)/2^2),2)*MOD(INT(MOD(INT((F9)/65536),256)/2^2),2)*4+MOD(INT(MOD(INT(((4294967295-D9))/65536),256)/2^3),2)*MOD(INT(MOD(INT((F9)/65536),256)/2^3),2)*8+MOD(INT(MOD(INT(((4294967295-D9))/65536),256)/2^4),2)*MOD(INT(MOD(INT((F9)/65536),256)/2^4),2)*16+MOD(INT(MOD(INT(((4294967295-D9))/65536),256)/2^5),2)*MOD(INT(MOD(INT((F9)/65536),256)/2^5),2)*32+MOD(INT(MOD(INT(((4294967295-D9))/65536),256)/2^6),2)*MOD(INT(MOD(INT((F9)/65536),256)/2^6),2)*64+MOD(INT(MOD(INT(((4294967295-D9))/65536),256)/2^7),2)*MOD(INT(MOD(INT((F9)/65536),256)/2^7),2)*128)*65536+(MOD(INT(MOD(INT(((4294967295-D9))/16777216),256)/2^0),2)*MOD(INT(MOD(INT((F9)/16777216),256)/2^0),2)*1+MOD(INT(MOD(INT(((4294967295-D9))/16777216),256)/2^1),2)*MOD(INT(MOD(INT((F9)/16777216),256)/2^1),2)*2+MOD(INT(MOD(INT(((4294967295-D9))/16777216),256)/2^2),2)*MOD(INT(MOD(INT((F9)/16777216),256)/2^2),2)*4+MOD(INT(MOD(INT(((4294967295-D9))/16777216),256)/2^3),2)*MOD(INT(MOD(INT((F9)/16777216),256)/2^3),2)*8+MOD(INT(MOD(INT(((4294967295-D9))/16777216),256)/2^4),2)*MOD(INT(MOD(INT((F9)/16777216),256)/2^4),2)*16+MOD(INT(MOD(INT(((4294967295-D9))/16777216),256)/2^5),2)*MOD(INT(MOD(INT((F9)/16777216),256)/2^5),2)*32+MOD(INT(MOD(INT(((4294967295-D9))/16777216),256)/2^6),2)*MOD(INT(MOD(INT((F9)/16777216),256)/2^6),2)*64+MOD(INT(MOD(INT(((4294967295-D9))/16777216),256)/2^7),2)*MOD(INT(MOD(INT((F9)/16777216),256)/2^7),2)*128)*16777216) -> 5944 | I10: — | J10: =MOD(G10+H10,4294967296) -> 1611642 | K10: =(0)+(0)*256+(0)*65536+(0)*16777216 -> 0 | L10: ='📦 MD5 Constants'!C8 -> 4118548399 | M10: ='📦 MD5 Constants'!H8 -> 7 | N10: =MOD(C9+J10+K10+'📦 MD5 Constants'!C8,4294967296) -> 3504816723 | O10: =MOD(MOD(N10,2^25)*2^7+INT(N10/2^25),4294967296) -> 1939941864 | P10: =D10 -> 262009391 | Q10: op=5 g=M[4] shift=7
B11: 6 | C11: =F10 -> 605655266 | D11: =MOD(D10+O11,4294967296) -> 2575600242 | E11: =D10 -> 262009391 | F11: =E10 -> 2617034823 | G11: =((MOD(INT(MOD(INT((D10)/1),256)/2^0),2)*MOD(INT(MOD(INT((E10)/1),256)/2^0),2)*1+MOD(INT(MOD(INT((D10)/1),256)/2^1),2)*MOD(INT(MOD(INT((E10)/1),256)/2^1),2)*2+MOD(INT(MOD(INT((D10)/1),256)/2^2),2)*MOD(INT(MOD(INT((E10)/1),256)/2^2),2)*4+MOD(INT(MOD(INT((D10)/1),256)/2^3),2)*MOD(INT(MOD(INT((E10)/1),256)/2^3),2)*8+MOD(INT(MOD(INT((D10)/1),256)/2^4),2)*MOD(INT(MOD(INT((E10)/1),256)/2^4),2)*16+MOD(INT(MOD(INT((D10)/1),256)/2^5),2)*MOD(INT(MOD(INT((E10)/1),256)/2^5),2)*32+MOD(INT(MOD(INT((D10)/1),256)/2^6),2)*MOD(INT(MOD(INT((E10)/1),256)/2^6),2)*64+MOD(INT(MOD(INT((D10)/1),256)/2^7),2)*MOD(INT(MOD(INT((E10)/1),256)/2^7),2)*128)*1+(MOD(INT(MOD(INT((D10)/256),256)/2^0),2)*MOD(INT(MOD(INT((E10)/256),256)/2^0),2)*1+MOD(INT(MOD(INT((D10)/256),256)/2^1),2)*MOD(INT(MOD(INT((E10)/256),256)/2^1),2)*2+MOD(INT(MOD(INT((D10)/256),256)/2^2),2)*MOD(INT(MOD(INT((E10)/256),256)/2^2),2)*4+MOD(INT(MOD(INT((D10)/256),256)/2^3),2)*MOD(INT(MOD(INT((E10)/256),256)/2^3),2)*8+MOD(INT(MOD(INT((D10)/256),256)/2^4),2)*MOD(INT(MOD(INT((E10)/256),256)/2^4),2)*16+MOD(INT(MOD(INT((D10)/256),256)/2^5),2)*MOD(INT(MOD(INT((E10)/256),256)/2^5),2)*32+MOD(INT(MOD(INT((D10)/256),256)/2^6),2)*MOD(INT(MOD(INT((E10)/256),256)/2^6),2)*64+MOD(INT(MOD(INT((D10)/256),256)/2^7),2)*MOD(INT(MOD(INT((E10)/256),256)/2^7),2)*128)*256+(MOD(INT(MOD(INT((D10)/65536),256)/2^0),2)*MOD(INT(MOD(INT((E10)/65536),256)/2^0),2)*1+MOD(INT(MOD(INT((D10)/65536),256)/2^1),2)*MOD(INT(MOD(INT((E10)/65536),256)/2^1),2)*2+MOD(INT(MOD(INT((D10)/65536),256)/2^2),2)*MOD(INT(MOD(INT((E10)/65536),256)/2^2),2)*4+MOD(INT(MOD(INT((D10)/65536),256)/2^3),2)*MOD(INT(MOD(INT((E10)/65536),256)/2^3),2)*8+MOD(INT(MOD(INT((D10)/65536),256)/2^4),2)*MOD(INT(MOD(INT((E10)/65536),256)/2^4),2)*16+MOD(INT(MOD(INT((D10)/65536),256)/2^5),2)*MOD(INT(MOD(INT((E10)/65536),256)/2^5),2)*32+MOD(INT(MOD(INT((D10)/65536),256)/2^6),2)*MOD(INT(MOD(INT((E10)/65536),256)/2^6),2)*64+MOD(INT(MOD(INT((D10)/65536),256)/2^7),2)*MOD(INT(MOD(INT((E10)/65536),256)/2^7),2)*128)*65536+(MOD(INT(MOD(INT((D10)/16777216),256)/2^0),2)*MOD(INT(MOD(INT((E10)/16777216),256)/2^0),2)*1+MOD(INT(MOD(INT((D10)/16777216),256)/2^1),2)*MOD(INT(MOD(INT((E10)/16777216),256)/2^1),2)*2+MOD(INT(MOD(INT((D10)/16777216),256)/2^2),2)*MOD(INT(MOD(INT((E10)/16777216),256)/2^2),2)*4+MOD(INT(MOD(INT((D10)/16777216),256)/2^3),2)*MOD(INT(MOD(INT((E10)/16777216),256)/2^3),2)*8+MOD(INT(MOD(INT((D10)/16777216),256)/2^4),2)*MOD(INT(MOD(INT((E10)/16777216),256)/2^4),2)*16+MOD(INT(MOD(INT((D10)/16777216),256)/2^5),2)*MOD(INT(MOD(INT((E10)/16777216),256)/2^5),2)*32+MOD(INT(MOD(INT((D10)/16777216),256)/2^6),2)*MOD(INT(MOD(INT((E10)/16777216),256)/2^6),2)*64+MOD(INT(MOD(INT((D10)/16777216),256)/2^7),2)*MOD(INT(MOD(INT((E10)/16777216),256)/2^7),2)*128)*16777216) -> 194822151 | H11: =((MOD(INT(MOD(INT(((4294967295-D10))/1),256)/2^0),2)*MOD(INT(MOD(INT((F10)/1),256)/2^0),2)*1+MOD(INT(MOD(INT(((4294967295-D10))/1),256)/2^1),2)*MOD(INT(MOD(INT((F10)/1),256)/2^1),2)*2+MOD(INT(MOD(INT(((4294967295-D10))/1),256)/2^2),2)*MOD(INT(MOD(INT((F10)/1),256)/2^2),2)*4+MOD(INT(MOD(INT(((4294967295-D10))/1),256)/2^3),2)*MOD(INT(MOD(INT((F10)/1),256)/2^3),2)*8+MOD(INT(MOD(INT(((4294967295-D10))/1),256)/2^4),2)*MOD(INT(MOD(INT((F10)/1),256)/2^4),2)*16+MOD(INT(MOD(INT(((4294967295-D10))/1),256)/2^5),2)*MOD(INT(MOD(INT((F10)/1),256)/2^5),2)*32+MOD(INT(MOD(INT(((4294967295-D10))/1),256)/2^6),2)*MOD(INT(MOD(INT((F10)/1),256)/2^6),2)*64+MOD(INT(MOD(INT(((4294967295-D10))/1),256)/2^7),2)*MOD(INT(MOD(INT((F10)/1),256)/2^7),2)*128)*1+(MOD(INT(MOD(INT(((4294967295-D10))/256),256)/2^0),2)*MOD(INT(MOD(INT((F10)/256),256)/2^0),2)*1+MOD(INT(MOD(INT(((4294967295-D10))/256),256)/2^1),2)*MOD(INT(MOD(INT((F10)/256),256)/2^1),2)*2+MOD(INT(MOD(INT(((4294967295-D10))/256),256)/2^2),2)*MOD(INT(MOD(INT((F10)/256),256)/2^2),2)*4+MOD(INT(MOD(INT(((4294967295-D10))/256),256)/2^3),2)*MOD(INT(MOD(INT((F10)/256),256)/2^3),2)*8+MOD(INT(MOD(INT(((4294967295-D10))/256),256)/2^4),2)*MOD(INT(MOD(INT((F10)/256),256)/2^4),2)*16+MOD(INT(MOD(INT(((4294967295-D10))/256),256)/2^5),2)*MOD(INT(MOD(INT((F10)/256),256)/2^5),2)*32+MOD(INT(MOD(INT(((4294967295-D10))/256),256)/2^6),2)*MOD(INT(MOD(INT((F10)/256),256)/2^6),2)*64+MOD(INT(MOD(INT(((4294967295-D10))/256),256)/2^7),2)*MOD(INT(MOD(INT((F10)/256),256)/2^7),2)*128)*256+(MOD(INT(MOD(INT(((4294967295-D10))/65536),256)/2^0),2)*MOD(INT(MOD(INT((F10)/65536),256)/2^0),2)*1+MOD(INT(MOD(INT(((4294967295-D10))/65536),256)/2^1),2)*MOD(INT(MOD(INT((F10)/65536),256)/2^1),2)*2+MOD(INT(MOD(INT(((4294967295-D10))/65536),256)/2^2),2)*MOD(INT(MOD(INT((F10)/65536),256)/2^2),2)*4+MOD(INT(MOD(INT(((4294967295-D10))/65536),256)/2^3),2)*MOD(INT(MOD(INT((F10)/65536),256)/2^3),2)*8+MOD(INT(MOD(INT(((4294967295-D10))/65536),256)/2^4),2)*MOD(INT(MOD(INT((F10)/65536),256)/2^4),2)*16+MOD(INT(MOD(INT(((4294967295-D10))/65536),256)/2^5),2)*MOD(INT(MOD(INT((F10)/65536),256)/2^5),2)*32+MOD(INT(MOD(INT(((4294967295-D10))/65536),256)/2^6),2)*MOD(INT(MOD(INT((F10)/65536),256)/2^6),2)*64+MOD(INT(MOD(INT(((4294967295-D10))/65536),256)/2^7),2)*MOD(INT(MOD(INT((F10)/65536),256)/2^7),2)*128)*65536+(MOD(INT(MOD(INT(((4294967295-D10))/16777216),256)/2^0),2)*MOD(INT(MOD(INT((F10)/16777216),256)/2^0),2)*1+MOD(INT(MOD(INT(((4294967295-D10))/16777216),256)/2^1),2)*MOD(INT(MOD(INT((F10)/16777216),256)/2^1),2)*2+MOD(INT(MOD(INT(((4294967295-D10))/16777216),256)/2^2),2)*MOD(INT(MOD(INT((F10)/16777216),256)/2^2),2)*4+MOD(INT(MOD(INT(((4294967295-D10))/16777216),256)/2^3),2)*MOD(INT(MOD(INT((F10)/16777216),256)/2^3),2)*8+MOD(INT(MOD(INT(((4294967295-D10))/16777216),256)/2^4),2)*MOD(INT(MOD(INT((F10)/16777216),256)/2^4),2)*16+MOD(INT(MOD(INT(((4294967295-D10))/16777216),256)/2^5),2)*MOD(INT(MOD(INT((F10)/16777216),256)/2^5),2)*32+MOD(INT(MOD(INT(((4294967295-D10))/16777216),256)/2^6),2)*MOD(INT(MOD(INT((F10)/16777216),256)/2^6),2)*64+MOD(INT(MOD(INT(((4294967295-D10))/16777216),256)/2^7),2)*MOD(INT(MOD(INT((F10)/16777216),256)/2^7),2)*128)*16777216) -> 536871104 | I11: — | J11: =MOD(G11+H11,4294967296) -> 731693255 | K11: =(0)+(0)*256+(0)*65536+(0)*16777216 -> 0 | L11: ='📦 MD5 Constants'!C9 -> 1200080426 | M11: ='📦 MD5 Constants'!H9 -> 12 | N11: =MOD(C10+J11+K11+'📦 MD5 Constants'!C9,4294967296) -> 2218303081 | O11: =MOD(MOD(N11,2^20)*2^12+INT(N11/2^20),4294967296) -> 2313590851 | P11: =D11 -> 2575600242 | Q11: op=6 g=M[5] shift=12
B12: 7 | C12: =F11 -> 2617034823 | D12: =MOD(D11+O12,4294967296) -> 3418241791 | E12: =D11 -> 2575600242 | F12: =E11 -> 262009391 | G12: =((MOD(INT(MOD(INT((D11)/1),256)/2^0),2)*MOD(INT(MOD(INT((E11)/1),256)/2^0),2)*1+MOD(INT(MOD(INT((D11)/1),256)/2^1),2)*MOD(INT(MOD(INT((E11)/1),256)/2^1),2)*2+MOD(INT(MOD(INT((D11)/1),256)/2^2),2)*MOD(INT(MOD(INT((E11)/1),256)/2^2),2)*4+MOD(INT(MOD(INT((D11)/1),256)/2^3),2)*MOD(INT(MOD(INT((E11)/1),256)/2^3),2)*8+MOD(INT(MOD(INT((D11)/1),256)/2^4),2)*MOD(INT(MOD(INT((E11)/1),256)/2^4),2)*16+MOD(INT(MOD(INT((D11)/1),256)/2^5),2)*MOD(INT(MOD(INT((E11)/1),256)/2^5),2)*32+MOD(INT(MOD(INT((D11)/1),256)/2^6),2)*MOD(INT(MOD(INT((E11)/1),256)/2^6),2)*64+MOD(INT(MOD(INT((D11)/1),256)/2^7),2)*MOD(INT(MOD(INT((E11)/1),256)/2^7),2)*128)*1+(MOD(INT(MOD(INT((D11)/256),256)/2^0),2)*MOD(INT(MOD(INT((E11)/256),256)/2^0),2)*1+MOD(INT(MOD(INT((D11)/256),256)/2^1),2)*MOD(INT(MOD(INT((E11)/256),256)/2^1),2)*2+MOD(INT(MOD(INT((D11)/256),256)/2^2),2)*MOD(INT(MOD(INT((E11)/256),256)/2^2),2)*4+MOD(INT(MOD(INT((D11)/256),256)/2^3),2)*MOD(INT(MOD(INT((E11)/256),256)/2^3),2)*8+MOD(INT(MOD(INT((D11)/256),256)/2^4),2)*MOD(INT(MOD(INT((E11)/256),256)/2^4),2)*16+MOD(INT(MOD(INT((D11)/256),256)/2^5),2)*MOD(INT(MOD(INT((E11)/256),256)/2^5),2)*32+MOD(INT(MOD(INT((D11)/256),256)/2^6),2)*MOD(INT(MOD(INT((E11)/256),256)/2^6),2)*64+MOD(INT(MOD(INT((D11)/256),256)/2^7),2)*MOD(INT(MOD(INT((E11)/256),256)/2^7),2)*128)*256+(MOD(INT(MOD(INT((D11)/65536),256)/2^0),2)*MOD(INT(MOD(INT((E11)/65536),256)/2^0),2)*1+MOD(INT(MOD(INT((D11)/65536),256)/2^1),2)*MOD(INT(MOD(INT((E11)/65536),256)/2^1),2)*2+MOD(INT(MOD(INT((D11)/65536),256)/2^2),2)*MOD(INT(MOD(INT((E11)/65536),256)/2^2),2)*4+MOD(INT(MOD(INT((D11)/65536),256)/2^3),2)*MOD(INT(MOD(INT((E11)/65536),256)/2^3),2)*8+MOD(INT(MOD(INT((D11)/65536),256)/2^4),2)*MOD(INT(MOD(INT((E11)/65536),256)/2^4),2)*16+MOD(INT(MOD(INT((D11)/65536),256)/2^5),2)*MOD(INT(MOD(INT((E11)/65536),256)/2^5),2)*32+MOD(INT(MOD(INT((D11)/65536),256)/2^6),2)*MOD(INT(MOD(INT((E11)/65536),256)/2^6),2)*64+MOD(INT(MOD(INT((D11)/65536),256)/2^7),2)*MOD(INT(MOD(INT((E11)/65536),256)/2^7),2)*128)*65536+(MOD(INT(MOD(INT((D11)/16777216),256)/2^0),2)*MOD(INT(MOD(INT((E11)/16777216),256)/2^0),2)*1+MOD(INT(MOD(INT((D11)/16777216),256)/2^1),2)*MOD(INT(MOD(INT((E11)/16777216),256)/2^1),2)*2+MOD(INT(MOD(INT((D11)/16777216),256)/2^2),2)*MOD(INT(MOD(INT((E11)/16777216),256)/2^2),2)*4+MOD(INT(MOD(INT((D11)/16777216),256)/2^3),2)*MOD(INT(MOD(INT((E11)/16777216),256)/2^3),2)*8+MOD(INT(MOD(INT((D11)/16777216),256)/2^4),2)*MOD(INT(MOD(INT((E11)/16777216),256)/2^4),2)*16+MOD(INT(MOD(INT((D11)/16777216),256)/2^5),2)*MOD(INT(MOD(INT((E11)/16777216),256)/2^5),2)*32+MOD(INT(MOD(INT((D11)/16777216),256)/2^6),2)*MOD(INT(MOD(INT((E11)/16777216),256)/2^6),2)*64+MOD(INT(MOD(INT((D11)/16777216),256)/2^7),2)*MOD(INT(MOD(INT((E11)/16777216),256)/2^7),2)*128)*16777216) -> 159679010 | H12: =((MOD(INT(MOD(INT(((4294967295-D11))/1),256)/2^0),2)*MOD(INT(MOD(INT((F11)/1),256)/2^0),2)*1+MOD(INT(MOD(INT(((4294967295-D11))/1),256)/2^1),2)*MOD(INT(MOD(INT((F11)/1),256)/2^1),2)*2+MOD(INT(MOD(INT(((4294967295-D11))/1),256)/2^2),2)*MOD(INT(MOD(INT((F11)/1),256)/2^2),2)*4+MOD(INT(MOD(INT(((4294967295-D11))/1),256)/2^3),2)*MOD(INT(MOD(INT((F11)/1),256)/2^3),2)*8+MOD(INT(MOD(INT(((4294967295-D11))/1),256)/2^4),2)*MOD(INT(MOD(INT((F11)/1),256)/2^4),2)*16+MOD(INT(MOD(INT(((4294967295-D11))/1),256)/2^5),2)*MOD(INT(MOD(INT((F11)/1),256)/2^5),2)*32+MOD(INT(MOD(INT(((4294967295-D11))/1),256)/2^6),2)*MOD(INT(MOD(INT((F11)/1),256)/2^6),2)*64+MOD(INT(MOD(INT(((4294967295-D11))/1),256)/2^7),2)*MOD(INT(MOD(INT((F11)/1),256)/2^7),2)*128)*1+(MOD(INT(MOD(INT(((4294967295-D11))/256),256)/2^0),2)*MOD(INT(MOD(INT((F11)/256),256)/2^0),2)*1+MOD(INT(MOD(INT(((4294967295-D11))/256),256)/2^1),2)*MOD(INT(MOD(INT((F11)/256),256)/2^1),2)*2+MOD(INT(MOD(INT(((4294967295-D11))/256),256)/2^2),2)*MOD(INT(MOD(INT((F11)/256),256)/2^2),2)*4+MOD(INT(MOD(INT(((4294967295-D11))/256),256)/2^3),2)*MOD(INT(MOD(INT((F11)/256),256)/2^3),2)*8+MOD(INT(MOD(INT(((4294967295-D11))/256),256)/2^4),2)*MOD(INT(MOD(INT((F11)/256),256)/2^4),2)*16+MOD(INT(MOD(INT(((4294967295-D11))/256),256)/2^5),2)*MOD(INT(MOD(INT((F11)/256),256)/2^5),2)*32+MOD(INT(MOD(INT(((4294967295-D11))/256),256)/2^6),2)*MOD(INT(MOD(INT((F11)/256),256)/2^6),2)*64+MOD(INT(MOD(INT(((4294967295-D11))/256),256)/2^7),2)*MOD(INT(MOD(INT((F11)/256),256)/2^7),2)*128)*256+(MOD(INT(MOD(INT(((4294967295-D11))/65536),256)/2^0),2)*MOD(INT(MOD(INT((F11)/65536),256)/2^0),2)*1+MOD(INT(MOD(INT(((4294967295-D11))/65536),256)/2^1),2)*MOD(INT(MOD(INT((F11)/65536),256)/2^1),2)*2+MOD(INT(MOD(INT(((4294967295-D11))/65536),256)/2^2),2)*MOD(INT(MOD(INT((F11)/65536),256)/2^2),2)*4+MOD(INT(MOD(INT(((4294967295-D11))/65536),256)/2^3),2)*MOD(INT(MOD(INT((F11)/65536),256)/2^3),2)*8+MOD(INT(MOD(INT(((4294967295-D11))/65536),256)/2^4),2)*MOD(INT(MOD(INT((F11)/65536),256)/2^4),2)*16+MOD(INT(MOD(INT(((4294967295-D11))/65536),256)/2^5),2)*MOD(INT(MOD(INT((F11)/65536),256)/2^5),2)*32+MOD(INT(MOD(INT(((4294967295-D11))/65536),256)/2^6),2)*MOD(INT(MOD(INT((F11)/65536),256)/2^6),2)*64+MOD(INT(MOD(INT(((4294967295-D11))/65536),256)/2^7),2)*MOD(INT(MOD(INT((F11)/65536),256)/2^7),2)*128)*65536+(MOD(INT(MOD(INT(((4294967295-D11))/16777216),256)/2^0),2)*MOD(INT(MOD(INT((F11)/16777216),256)/2^0),2)*1+MOD(INT(MOD(INT(((4294967295-D11))/16777216),256)/2^1),2)*MOD(INT(MOD(INT((F11)/16777216),256)/2^1),2)*2+MOD(INT(MOD(INT(((4294967295-D11))/16777216),256)/2^2),2)*MOD(INT(MOD(INT((F11)/16777216),256)/2^2),2)*4+MOD(INT(MOD(INT(((4294967295-D11))/16777216),256)/2^3),2)*MOD(INT(MOD(INT((F11)/16777216),256)/2^3),2)*8+MOD(INT(MOD(INT(((4294967295-D11))/16777216),256)/2^4),2)*MOD(INT(MOD(INT((F11)/16777216),256)/2^4),2)*16+MOD(INT(MOD(INT(((4294967295-D11))/16777216),256)/2^5),2)*MOD(INT(MOD(INT((F11)/16777216),256)/2^5),2)*32+MOD(INT(MOD(INT(((4294967295-D11))/16777216),256)/2^6),2)*MOD(INT(MOD(INT((F11)/16777216),256)/2^6),2)*64+MOD(INT(MOD(INT(((4294967295-D11))/16777216),256)/2^7),2)*MOD(INT(MOD(INT((F11)/16777216),256)/2^7),2)*128)*16777216) -> 41435141 | I12: — | J12: =MOD(G12+H12,4294967296) -> 201114151 | K12: =(0)+(0)*256+(0)*65536+(0)*16777216 -> 0 | L12: ='📦 MD5 Constants'!C10 -> 2821735955 | M12: ='📦 MD5 Constants'!H10 -> 17 | N12: =MOD(C11+J12+K12+'📦 MD5 Constants'!C10,4294967296) -> 3628505372 | O12: =MOD(MOD(N12,2^15)*2^17+INT(N12/2^15),4294967296) -> 842641549 | P12: =D12 -> 3418241791 | Q12: op=7 g=M[6] shift=17
